Workbook

Sheet DB
A1: ID paziente | B1: ='Scheda descrittiva parametri'!B1 -> Neonatal | C1: ='Scheda descrittiva parametri'!C1 -> Febbre | D1: ='Scheda descrittiva parametri'!D1 -> valore_temperatura_massima | E1: ='Scheda descrittiva parametri'!E1 -> data_temperatura_max | F1: ='Scheda descrittiva parametri'!F1 -> Ipotermia | G1: ='Scheda descrittiva parametri'!G1 -> valore_temperatura_min | H1: ='Scheda descrittiva parametri'!H1 -> data_temperatura_min | I1: ='Scheda descrittiva parametri'!I1 -> Brividi | ... L1: ='Scheda descrittiva parametri'!L1 -> valore_pressione_sistolica_min | M1: ='Scheda descrittiva parametri'!O1 -> data_valore_pressione_diastolica_min | N1: ='Scheda descrittiva parametri'!P1 -> tachicardia | O1: ='Scheda descrittiva parametri'!Q1 -> valore_frequenza_cardiaca_max | P1: ='Scheda descrittiva parametri'!R1 -> data_frequenza_max | Q1: ='Scheda descrittiva parametri'!S1 -> bradicardia | R1: ='Scheda descrittiva parametri'!T1 -> valore_frequenza_cardiaca_min | S1: ='Scheda descrittiva parametri'!U1 -> data_frequenza_min | T1: ='Scheda descrittiva parametri'!V1 -> apnea | ... GY1: ='Scheda descrittiva parametri'!HA1

Sheet Scheda descrittiva parametri
A1: Parametro | B1: Neonatal | C1: Febbre | D1: valore_temperatura_massima | E1: data_temperatura_max | F1: Ipotermia | G1: valore_temperatura_min | H1: data_temperatura_min | I1: Brividi | J1: data_brividi | K1: ipotensione | L1: valore_pressione_sistolica_min | M1: data_valore_pressione_sistolica_min | N1: valore_pressione_diastolica_min | O1: data_valore_pressione_diastolica_min | P1: tachicardia | Q1: valore_frequenza_cardiaca_max | R1: data_frequenza_max | S1: bradicardia | T1: valore_frequenza_cardiaca_min | U1: data_frequenza_min | V1: apnea | W1: apnea_lunga | X1: apnea_corta | Y1: tempo_apnea_max | Z1: data_apnea_max | AA1: cianosi | AB1: data_cianosi | AC1: pallore | AD1: data_pallore | AE1: ipotonia_marcata | AF1: data_ipotonia | AG1: n_emocolture_positive | AH1: data_emocoltura_positiva1 | AI1: ora_emocoltura1 | AJ1: data_emocoltura_positiva2 | AK1: ora_emocoltura2 | AL1: distanza_emocolture_ore | AM1: distanza_emocolture<48h | AN1: nome_microrganismo_isolato1 | AO1: patogeno_riconosciuto1 | AP1: contaminante_pelle1 | AQ1: nome_microrganismo_isolato2 | AR1: patogeno_riconosciuto2 | AS1: contaminante_pelle2 | AT1: CNS_emocoltura | AU1: n_colture_liquido_cerebrospinale_pos | AV1: data_coltura_liquido_cerebrospinale | AW1: nome_patogeno_liquido_cerebrospinale | AX1: CNS_liquido_cerebrospinale | AY1: n_isolamento_da_cvc | AZ1: data_isolamento_da_cvc | BA1: ora_isolamento_da_cvc | BB1: nome_microrganismo_cvc | BC1: CNS_cvc | BD1: n_isolamento_da_pvc | BE1: data_isolamento_da_pvc | BF1: ora_isolamento_da_pvc | BG1: nome_microrganismo_pvc | BH1: CNS_pvc | BI1: PCR | BJ1: PCR_max | BK1: data_PCR_max | BL1: I/T_ratio | BM1: I/T_ratio_max | BN1: data_I/T_ratio_max | BO1: leukocytes | BP1: leukocytes_min | BQ1: data_leukocytes_min | BR1: platelets | BS1: platelets_min | BT1: data_platelets_min | BU1: data_ingresso_in_ospedale | BV1: ora_ingresso_in_ospedale | BW1: luogo_origine_pz | BX1: data_inserimento_dispositivo | BY1: dispositivo_antecedente | BZ1: tipo_dispositivo_inserito | CA1: nato_in_ospedale | CB1: data_rimozione_cvc | CC1: ora_rimozione_cvc | CD1: carica_batterica_catetere_quantitativa | CE1: carica_batterica_catetere_semiquantitativa | CF1: blood_culture_ratio | CG1: dd_positivity_cultures | CH1: dd_positivity_cultures_tempo | CI1: culture_positivity_cvc_pus | CJ1: date_culture_cvc_pus | CK1: microrganismo_isolato_pus_cvc | CL1: culture_positivity_pvc_pus | CM1: date_culture_cvp_pus | CN1: microrganismo_isolato_pus_pvc | CO1: Miglioramento_clinico_post-rimozione_catetere | CP1: data_rimozione_catetere | CQ1: TC_pre-rimozione_cat | CR1: TC_48h_post-rimozione_cat | CS1: miglioramento_TC_48h_dopo | CT1: eritema_pre-rimozione_cat | CU1: eritema_48h_post-rimozione_cat | CV1: miglioramento_eritema_48h_dopo | CW1: pus_pre-rimozione_cat | CX1: pus_48h_post-rimozione_cat | CY1: miglioramento_pus_48h_dopo | CZ1: coltura_BAL_pos | DA1: data_coltura_BAL_pos | DB1: microrganismo_BAL | DC1: coltura_aspirato_tracheale_pos | DD1: data_coltura_aspirato_tracheale_pos | DE1: microrganismo_aspirato_tracheale | DF1: coltura_escreato_pos | DG1: data_coltura_escreato_pos | DH1: microrganismo_escreato | DI1: urinocoltura_pos | DJ1: data_urinocoltura_pos | DK1: microrganismo_urinocoltura | DL1: tampone_ferita_chirurgica_pos | DM1: data_tampone_ferita_chirurgica_pos | DN1: microrganismo_tampone_ferita_chirurgica | DO1: biopsia_tessuto_pos | DP1: data_biopsia_tessuto_pos | DQ1: microrganismo_biopsia_tessuto | DR1: coltura_ascesso_pos | DS1: data_coltura_ascesso_pos | DT1: microrganismo_coltura_ascesso | DU1: coltura_protesi_pos | DV1: data_coltura_protesi_pos | DW1: microrganismo_coltura_protesi | DX1: rx_torace_infiltrato | DY1: rx_torace_consolidamento | DZ1: rx_torace_cavitazione | EA1: tc_torace_segni_polmonite | EB1: sintomo_tosse | EC1: sintomo_dispnea | ED1: sintomo_tachipnea | EE1: segno_espettorato_purulento | EF1: segno_emottisi | EG1: auscultazione_ronchi | EH1: auscultazione_suoni_resp_alterati | EI1: desaturazione | EJ1: sintomo_urgenza_minzionale | EK1: sintomo_pollachiuria | EL1: sintomo_disuria | EM1: sintomo_dolore_sovrapubico | EN1: segno_giordano_pos | EO1: presenza_catetere_vescicale | EP1: imaging_ascesso_addominale | EQ1: osservazione_chirurgica_pus | ER1: osservazione_chirurgica_ascesso | ES1: sintomo_nausea | ET1: sintomo_vomito | EU1: sintomo_dolore_addominale | EV1: segno_addome_acuto | EW1: drenaggio_purulento_addome | EX1: ssi_pus | EY1: ssi_dolore | EZ1: ssi_edema | FA1: ssi_eritema | FB1: ssi_calore_locale | FC1: ssi_deiscenza_spontanea | FD1: ssi_apertura_dal_chirurgo | FE1: ssi_diagnosi_medica | FF1: sst_secrezione_purulenta | FG1: sst_pustole | FH1: sst_foruncoli | FI1: sst_dolore_localizzato | FJ1: sst_calore_localizzato | FK1: decu_arrossamento_bordi | FL1: decu_indurimento_bordi | FM1: decu_secrezione_purulenta | FN1: bone_imaging_pos | FO1: bone_dolore_locale | FP1: bone_gonfiore_locale | FQ1: men_cefalea | FR1: men_rigidita_nucale | FS1: men_segni_nervi_cranici | FT1: liquor_leucociti_elevati | FU1: liquor_glucosio_basso | FV1: endo_imaging_vegetazione | FW1: endo_nuovo_soffio | FX1: endo_ascesso_valvolare | FY1: BSI | FZ1: CA-BSI | GA1: HA-BSI | GB1: CRI3-CVC | GC1: CRI3-PVC | GD1: C-CVC | GE1: C-PVC | GF1: Secondarie | GG1: S-PUL | GH1: S-UTI | GI1: S-DIG | GJ1: S-SSI | GK1: S-SST | GL1: S-OTH | GM1: SCONOSCIUTA | GN1: NEO-LCBI | GO1: NEO-CNSB | GP1: CURR | GQ1: OHOSP | GR1: LTCF | GS1: OTHUNK
A2: Popolazione | B2: All | C2: All | D2: All | E2: All | F2: neonatale | G2: neonatale | H2: neonatale | I2: adulti | J2: adulti | K2: adulti | L2: adulti | M2: adulti | N2: adulti | O2: adulti | P2: neonatale | Q2: neonatale | R2: neonatale | S2: neonatale | T2: neonatale | U2: neonatale | V2: neonatale | W2: neonatale | X2: neonatale | Y2: neonatale | Z2: neonatale | AA2: neonatale | AB2: neonatale | AC2: neonatale | AD2: neonatale | AE2: neonatale | AF2: neonatale | AG2: All | AH2: All | AI2: All | AJ2: All | AK2: All | AL2: All | AM2: All | AN2: All | AO2: All | AP2: All | AQ2: All | AR2: All | AS2: All | AT2: neonatale | AU2: neonatale | AV2: neonatale | AW2: neonatale | AX2: neonatale | AY2: all | AZ2: all | BA2: adulti | BB2: all | BC2: neonatale | BD2: all | BE2: all | BF2: adulti | BG2: all | BH2: neonatale | BI2: neonatale | BJ2: neonatale | BK2: neonatale | BL2: neonatale | BM2: neonatale | BN2: neonatale | BO2: neonatale | BP2: neonatale | BQ2: neonatale | BR2: neonatale | BS2: neonatale | BT2: neonatale | BU2: adulti | BV2: adulti | BW2: adulti | BX2: adulti | BY2: adulti | BZ2: adulti | CA2: neonatale | CB2: adulti | CC2: adulti | CD2: adulti | CE2: adulti | CF2: adulti | CG2: adulti | CH2: adulti | CI2: adulti | CJ2: adulti | CK2: adulti | CL2: adulti | CM2: adulti | CN2: adulti | CO2: adulti | CP2: adulti | CQ2: adulti | CR2: adulti | CS2: adulti | CT2: adulti | CU2: adulti | CV2: adulti | CW2: adulti | CX2: adulti | CY2: adulti | CZ2: adulti | DA2: adulti | DB2: adulti | DC2: adulti | DD2: adulti | DE2: adulti | DF2: adulti | DG2: adulti | DH2: adulti | DI2: adulti | DJ2: adulti | DK2: adulti | DL2: adulti | DM2: adulti | DN2: adulti | DO2: adulti | DP2: adulti | DQ2: adulti | DR2: adulti | DS2: adulti | DT2: adulti | DU2: adulti | DV2: adulti | DW2: adulti | DX2: adulti | DY2: adulti | DZ2: adulti | EA2: adulti | EB2: adulti | EC2: adulti | ED2: adulti | EE2: adulti | EF2: adulti | EG2: adulti | EH2: adulti | EI2: adulti | EJ2: adulti | EK2: adulti | EL2: adulti | EM2: adulti | EN2: adulti | EO2: adulti | EP2: adulti | EQ2: adulti | ER2: adulti | ES2: adulti | ET2: adulti | EU2: adulti | EV2: adulti | EW2: adulti | EX2: adulti | EY2: adulti | EZ2: adulti | FA2: adulti | FB2: adulti | FC2: adulti | FD2: adulti | FE2: adulti | FF2: adulti | FG2: adulti | FH2: adulti | FI2: adulti | FJ2: adulti | FK2: adulti | FL2: adulti | FM2: adulti | FN2: adulti | FO2: adulti | FP2: adulti | FQ2: adulti | FR2: adulti | FS2: adulti | FT2: adulti | FU2: adulti | FV2: adulti | FW2: adulti | FX2: adulti | FY2: All | FZ2: All | GA2: All | GB2: adulti | GC2: adulti | GD2: adulti | GE2: adulti | GF2: adulti | GG2: adulti | GH2: adulti | GI2: adulti | GJ2: adulti | GK2: adulti | GL2: adulti | GM2: adulti | GN2: neonatale | GO2: neonatale | GP2: All | GQ2: All | GR2: adulti | GS2: All
A3: Descrizione del parametro | B3: Indica se il paziente è un neonato (età ≤ 30 giorni) o un adulto/pediatrico (età > 30 giorni) al momento dell'insorgenza dell'infezione. | C3: Presenza di febbre, definita come temperatura corporea maggiore o uguale a 38,0°C. | D3: Valore della temperatura corporea massima registrata. Espressa in °C. | E3: Data di rilevazione della temperatura corporea massima. | F3: Presenza di ipotermia, definita come temperatura corporea inferiore a 36,5°C. | G3: Valore della temperatura corporea minima registrata, espressa in °C. | H3: Data di rilevazione della temperatura corporea minima. | I3: Presenza di brividi (sensazione di freddo accompagnata da tremore muscolare involontario). | J3: Data di insorgenza o rilevazione dei brividi. | K3: Presenza di ipotensione, definita come pressione sistolica < 90mmHg o diastolica < 60mmHg. | L3: Valore della pressione arteriosa sistolica minima registrata. Espresso in mmHg. | M3: Data di rilevazione della pressione arteriosa sistolica minima. | N3: Valore della pressione arteriosa diastolica minima registrata. Espresso in mmHg. | O3: Data di rilevazione della pressione arteriosa diastolica minima. | P3: Presenza di tachicardia, definita come frequenza cardiaca superiore a 160bpm. | Q3: Valore della frequenza cardiaca massima registrata. Espressa in bpm. | R3: Data di rilevazione della frequenza cardiaca massima. | S3: Presenza di bradicardia, definita come frequenza cardiaca inferiore a 100bpm. | T3: Valore della frequenza cardiaca minima registrata. Espressa in bpm. | U3: Data di rilevazione della frequenza cardiaca minima. | V3: Presenza di apnea, definita come un'interruzione del respiro prolungata (apnea lunga) oppure breve (apnea corta) se associata a bradicardia, cianosi, pallore o ipotonia marcata. | W3: Presenza di apnea prolungata, definita come un'interruzione del respiro di durata uguale o superiore a 20 secondi. | X3: Presenza di apnea breve, definita come un'interruzione del respiro di durata compresa tra 5 e 19 secondi. | Y3: Il tempo di apnea massimo individuato nel diario clinico, espressa in secondi. | Z3: Data di rilevazione dell'episodio di apnea di durata massima. | AA3: Presenza di cianosi (colorazione bluastra o violacea della cute o delle mucose causata da ridotta ossigenazione). | AB3: Data di rilevazione della cianosi. | AC3: Presenza di pallore cutaneo (colorazione della pelle o delle mucose più chiara rispetto al normale, dovuta a ridotto flusso sanguigno o bassa emoglobina). | AD3: Data di rilevazione del pallore cutaneo. | AE3: Presenza di ipotonia marcata (riduzione severa del tono muscolare a riposo, postura a 'bambola di pezza' con arti appiattiti e marcata debolezza del collo nel sollevamento). | AF3: Data di rilevazione dell'ipotonia marcata. | AG3: Numero totale di emocolture con esito positivo registrate per il paziente. | AH3: Data del prelievo della prima emocoltura con esito positivo. | AI3: Ora del prelievo della prima emocoltura con esito positivo. | AJ3: Data del prelievo della seconda emocoltura con esito positivo. | AK3: Ora del prelievo della seconda emocoltura con esito positivo. | AL3: Intervallo temporale, espresso in ore, tra il prelievo della prima emocoltura e della seconda. | AM3: Indica se l'intervallo temporale tra il prelievo della prima e della seconda emocoltura è inferiore a 48 ore. | AN3: Nome del genere e della specie del microrganismo isolato nella prima emocoltura positiva. | AO3: Indica se il microrganismo isolato nella prima emocoltura è considerato un patogeno significativo, escludendo i comuni contaminanti (Stafilococchi coagulasi-negativi, Micrococcus sp., Propionibacterium acnes, Bacillus sp.). | AP3: Indica se il microrganismo isolato nella prima emocoltura è un potenziale contaminante (Stafilococchi coagulasi-negativi, Micrococcus sp., Propionibacterium acnes, Bacillus sp.). | AQ3: Nome del genere e della specie del microrganismo isolato nella seconda emocoltura positiva. | AR3: Indica se il microrganismo isolato nella seconda emocoltura è considerato un patogeno significativo, escludendo i comuni contaminanti (Stafilococchi coagulasi-negativi, Micrococcus sp., Propionibacterium acnes, Bacillus sp.). | AS3: Indica se il microrganismo isolato nella seconda emocoltura è un potenziale contaminante (Stafilococchi coagulasi-negativi, Micrococcus sp., Propionibacterium acnes, Bacillus sp.). | AT3: Indica se il microrganismo isolato è uno stafilococco coagulasi-negativo (CNS). | AU3: Numero totale di colture da liquido cerebrospinale con esito positivo registrate per il paziente. | AV3: Data di esecuzione del prelievo del liquido cerebrospinale (liquor) per l'esame colturale. | AW3: Nome del genere e della specie del microrganismo isolato dall'esame colturale del liquido cerebrospinale (liquor). | AX3: Indica se il microrganismo isolato dal liquido cerebrospinale (liquor) appartiene alla categoria degli stafilococchi coagulasi-negativi (CNS). | AY3: Numero totale di isolamenti microbiologici ottenuti da campioni prelevati tramite catetere venoso centrale - CVC. | AZ3: Data di esecuzione del prelievo microbiologico effettuato tramite catetere venoso centrale (CVC). | BA3: Ora di esecuzione del prelievo microbiologico effettuato tramite catetere venoso centrale (CVC). | BB3: Nome del genere e della specie del microrganismo isolato dal campione prelevato tramite catetere venoso centrale (CVC). | BC3: Indica se il microrganismo isolato dalla punta del catetere venoso centrale (o tramite prelievo da catetere CVC) appartiene alla categoria degli stafilococchi coagulasi-negativi (CNS). | BD3: Numero totale di isolamenti microbiologici ottenuti da campioni prelevati tramite catetere venoso periferico - CVP. | BE3: Data di esecuzione del prelievo microbiologico effettuato tramite catetere venoso periferico (CVP). | BF3: Ora di esecuzione del prelievo microbiologico effettuato tramite catetere venoso periferico (CVP). | BG3: Nome del genere e della specie del microrganismo isolato dal campione prelevato tramite catetere venoso periferico (CVP). | BH3: Indica se il microrganismo isolato dalla punta del catetere venoso periferico (o tramite prelievo da catetere CVP) appartiene alla categoria degli stafilococchi coagulasi-negativi (CNS). | BI3: Indica se il valore massimo di Proteina C Reattiva (PCR) registrato è superiore a 2,0 mg/dL. | BJ3: Valore massimo di Proteina C Reattiva (PCR) registrato. Espresso in mg/dL. | BK3: Data in cui è stato registrato il valore massimo di Proteina C Reattiva (PCR). | BL3: Indica se il rapporto tra neutrofili immaturi e neutrofili totali (I/T ratio) è superiore a 0,2. | BM3: Valore massimo registrato del rapporto tra neutrofili immaturi e totali (I/T ratio). | BN3: Data in cui è stato registrato il valore massimo del rapporto tra neutrofili immaturi e totali (I/T ratio). | BO3: Andiamo a vedere se i leukocytes < 5/nL | BP3: Valore minimo di leucociti (globuli bianchi) registrato. Espresso come "numero di leucociti/nL". | BQ3: Data in cui è stato registrato il valore minimo di leucociti (globuli bianchi). | BR3: Indica se il conteggio delle piastrine è inferiore a 100/nL. | BS3: Valore minimo di piastrine registrato espresso in "numero di piastrine/nL". | BT3: Data in cui è stato registrato il valore minimo di piastrine. | BU3: Data di ammissione del paziente presso la struttura ospedaliera, corrispondente alla prima annotazione cronologica del diario clinico. | BV3: Orario di ammissione del paziente presso la struttura ospedaliera, corrispondente alla prima annotazione temporale riportata nel diario clinico. | BW3: Luogo di provenienza del paziente al momento del ricovero (es. domicilio, RSA, altro ospedale, senza fissa dimora). | BX3: Data di posizionamento di un dispositivo medico invasivo (es. CVC, catetere vescicale, tubo endotracheale) avvenuto durante l'attuale ricovero e in data antecedente all'insorgenza dell'infezione. | BY3: Indica se il paziente era già portatore di un dispositivo medico invasivo (es. CVC, catetere vescicale, PEG, tracheostomia) al momento dell'ammissione in ospedale. | BZ3: Tipologia di dispositivo medico invasivo (es. CVC, CVP, catetere vescicale, tubo endotracheale) posizionato durante il ricovero attuale in data antecedente all'esordio dei sintomi. | CA3: Indica se la nascita del paziente è avvenuta all'interno della medesima struttura e durante lo stesso ricovero in cui si è verificato l'episodio di batteriemia (paziente inborn). | CB3: Data di rimozione del catetere venoso centrale (CVC) utilizzato per il prelievo microbiologico o presente al momento dell'infezione. | CC3: Orario di rimozione del catetere (CVC o CVP) utilizzato per il prelievo microbiologico o presente al momento dell'infezione. | CD3: Valore numerico della carica batterica isolata da campione di catetere tramite metodica quantitativa, espresso in Unità Formanti Colonia per millilitro (CFU/mL). | CE3: Valore numerico della carica batterica isolata da segmento di catetere tramite metodica semi-quantitativa, espresso in Unità Formanti Colonia (CFU). | CF3: Indica se il rapporto tra la carica batterica dell'emocoltura quantitativa da CVC e quella da sangue periferico è superiore a 5. | CG3: Indica se il Differential Time to Positivity (DTP) tra l'emocoltura da catetere (CVC) e quella da sangue periferico è superiore a 2 ore. | CH3: Valore numerico del differenziale temporale di positività (DTP) tra l'emocoltura da CVC e quella da sangue periferico (prelevate contemporaneamente). | CI3: Indica la presenza di colture microbiologiche positive da campioni di materiale purulento (pus) prelevati dal sito di inserzione cutanea o dal tunnel del catetere venoso centrale (CVC). | CJ3: Data in cui è stato eseguito il prelievo di materiale purulento (pus) dal sito di inserzione o dal tunnel del catetere (CVC) per l'esame colturale. | CK3: Nome del microrganismo (batterio o micete) identificato tramite esame colturale del materiale purulento (pus) prelevato dal sito di inserzione o dal tunnel del CVC. | CL3: Indica la presenza di colture microbiologiche positive da campioni di materiale purulento (pus) prelevati dal sito di inserzione cutanea di un catetere venoso periferico (CVP). | CM3: Data in cui è stato eseguito il prelievo di materiale purulento (pus) dal sito di inserzione di un catetere venoso periferico (CVP) per l'esame colturale. | CN3: Nome del microrganismo (batterio o micete) identificato tramite esame colturale del materiale purulento (pus) prelevato dal sito di inserzione di un catetere venoso periferico (CVP). | CO3: Indica se si è verificato un miglioramento del quadro clinico del paziente (es. defervescenza, scomparse eritema e/o pus al sito di inserzione) entro 48 ore dalla rimozione del catetere venoso (CVC o CVP). | CP3: Data di effettiva rimozione del catetere venoso (CVC o CVP) sospettato di essere la fonte dell'infezione, necessaria per il calcolo del miglioramento clinico a 48 ore. | CQ3: Valore dell'ultima temperatura corporea rilevata e documentata immediatamente prima della rimozione del catetere venoso (CVC o CVP). | CR3: Valore della temperatura corporea rilevata a distanza di 48 ore dalla rimozione del catetere venoso (CVC o CVP). | CS3: Indica se si è verificata una riduzione della temperatura corporea (defervescenza) o il ripristino della normotermia entro 48 ore dalla rimozione del catetere venoso (CVC o CVP). | CT3: Indica la presenza di eritema (arrossamento cutaneo) nel sito di inserzione del catetere (CVC o CVP) documentata nelle 48 ore precedenti la sua rimozione. | CU3: Indica la persistenza o la comparsa di eritema nel sito di precedente inserzione del catetere (CVC o CVP) rilevata a distanza di 48 ore dalla sua rimozione. | CV3: Indica se si è verificata una riduzione dell'estensione o dell'intensità dell'eritema (o la sua completa risoluzione) nel sito di inserzione entro 48 ore dalla rimozione del catetere (CVC o CVP). | CW3: Indica la presenza di secrezione purulenta (pus) nel sito di inserzione del catetere (CVC o CVP) documentata nelle 48 ore precedenti la sua rimozione. | CX3: Indica la persistenza o la comparsa di secrezione purulenta (pus) nel sito di precedente inserzione del catetere (CVC o CVP) rilevata a distanza di 48 ore dalla sua rimozione. | CY3: Indica se si è verificata la scomparsa o la significativa riduzione della secrezione purulenta (pus) nel sito di inserzione entro 48 ore dalla rimozione del catetere (CVC o CVP). | CZ3: Indica la positività microbiologica del Lavaggio Broncoalveolare (BAL), con carica batterica superiore alla soglia diagnostica (solitamente $\ge 10^4$ CFU/ml). | DA3: Data in cui è stata eseguita la procedura di Lavaggio Broncoalveolare (BAL) risultata positiva all'esame microbiologico. | DB3: Nome del microrganismo (batterio o micete) isolato e identificato tramite esame colturale del Lavaggio Broncoalveolare (BAL). | DC3: Indica la positività microbiologica dell'aspirato tracheale (ETA), con carica batterica superiore alla soglia diagnostica (solitamente $\ge 10^5$ CFU/ml). | DD3: Data in cui è stato eseguito il prelievo di aspirato tracheale (ETA) risultato positivo all'esame microbiologico. | DE3: Nome del microrganismo (batterio o micete) identificato tramite esame colturale quantitativo del secreto prelevato tramite aspirato tracheale (ETA). | DF3: Indica la positività microbiologica dell'esame colturale dell'escreato (espettorato), previa verifica dell'idoneità del campione tramite Score di Murray (presenza di leucociti e scarsità di cellule epiteliali). | DG3: Data in cui è stato raccolto il campione di escreato (espettorato) risultato positivo all'esame microbiologico. | DH3: Nome del microrganismo (batterio o micete) isolato tramite esame colturale del campione di escreato (espettorato) ritenuto clinicamente significativo. | DI3: Indica la positività microbiologica dell'urinocoltura, definita dalla presenza di una carica batterica significativa (solitamente $\ge 10^5$ CFU/ml) per uno o più patogeni urinari. | DJ3: Data in cui è stato raccolto il campione di urine risultato positivo all'esame microbiologico (urinocoltura). | DK3: Nome del microrganismo (batterio o micete) identificato tramite urinocoltura con carica batterica clinicamente significativa. | DL3: Indica la positività microbiologica del tampone eseguito su una ferita chirurgica, con isolamento di microrganismi patogeni. | DM3: Data in cui è stato effettuato il prelievo del tampone dalla ferita chirurgica risultato positivo all'esame microbiologico. | DN3: Nome del microrganismo (batterio o micete) identificato tramite l'esame colturale del tampone prelevato dalla ferita chirurgica. | DO3: Indica la positività microbiologica di un campione di tessuto prelevato tramite biopsia chirurgica o percutanea, con isolamento di microrganismi patogeni tramite coltura o esame istologico (colorazioni speciali). | DP3: Data in cui è stato effettuato il prelievo bioptico del tessuto (osseo, cutaneo profondo o d'organo) risultato positivo all'esame microbiologico o istologico. | DQ3: Nome del microrganismo (batterio o micete) identificato tramite esame colturale o indagini molecolari su campione di tessuto prelevato biopticamente. | DR3: Indica la positività microbiologica del materiale purulento prelevato da un ascesso tramite aspirazione percutanea o drenaggio chirurgico, con isolamento di microrganismi patogeni. | DS3: Data in cui è stato effettuato il prelievo del materiale purulento (tramite aspirazione o drenaggio di un ascesso) risultato positivo all'esame microbiologico. | DT3: Nome del microrganismo (batterio o micete) identificato tramite l'esame colturale del materiale purulento prelevato da una raccolta ascessuale. | DU3: Indica la positività microbiologica dell'esame colturale eseguito su una protesi rimossa (es. ortopedica, vascolare, valvolare) o sul liquido di sonicazione della stessa, con isolamento di microrganismi patogeni. | DV3: Data in cui è stata effettuata la rimozione chirurgica del dispositivo protesico o il prelievo del campione inviato per l'esame colturale (o sonicazione) risultato positivo. | DW3: Nome del microrganismo (batterio o micete) identificato tramite l'esame colturale o la tecnica di sonicazione della protesi rimossa. | DX3: Indica la presenza di nuovi o progressivi infiltrati polmonari, consolidamenti o opacità documentati tramite radiografia del torace (RX torace), compatibili con un quadro di polmonite. | DY3: Indica la presenza di aree di consolidamento parenchimale (addensamenti con perdita di aerazione polmonare) rilevate tramite radiografia del torace, suggestive di polmonite o focolaio infettivo. | DZ3: Indica la presenza di cavità all'interno di un'area di consolidamento polmonare (immagini a contenuto aereo o idroaereo) rilevate tramite radiografia del torace, suggestive di ascesso polmonare o necrosi tissutale. | EA3: Indica la presenza di segni radiologici documentati tramite Tomografia Computerizzata (TC) compatibili con polmonite, quali: aree di 'vetro smerigliato' (ground-glass), consolidamenti parenchimali, noduli con 'segno dell'alone' o linfoadenopatie ilari. | EB3: Indica la presenza di tosse riportata dal paziente o rilevata obiettivamente, sia essa di tipo secco (stizzosa) o produttivo (con espettorazione), come segno clinico di coinvolgimento delle vie respiratorie. | EC3: Indica la presenza di difficoltà respiratoria (fame d'aria) riferita dal paziente o rilevata obiettivamente, manifestata come aumento dello sforzo respiratorio, tachipnea o necessità di ossigenoterapia supplementare. | ED3: Indica un aumento della frequenza respiratoria superiore al limite normale (solitamente $> 20$ atti al minuto nell'adulto), rilevata durante l'esame obiettivo o tramite monitoraggio dei parametri vitali. | EE3: Indica la presenza di espettorato di aspetto purulento (giallastro o verdastro), denso e opaco, espulso tramite la tosse, indicativo di un'infezione batterica attiva delle vie respiratorie. | EF3: Indica l'emissione di sangue dalle vie respiratorie, solitamente tramite la tosse (espettorato ematico), proveniente dalla laringe, dalla trachea, dai bronchi o dal parenchima polmonare. | EG3: Indica la presenza di rumori respiratori patologici di tipo secco (ronchi) percepiti durante l'auscultazione toracica e prodotti dal passaggio dell'aria attraverso bronchi ostruiti da secrezioni dense o da edema della mucosa. | EH3: Indica una qualsiasi alterazione dei suoni fisiologici (murmure vescicolare) rilevata durante l'auscultazione del torace, che includa la riduzione o l'assenza del respiro (silenzio respiratorio) o la presenza di rumori aggiunti patologici non meglio specificati. | EI3: Indica una riduzione della saturazione di ossigeno nel sangue arterioso (SpO2) al di sotto dei valori normali (< 91%), rilevata tramite pulsossimetria o emogasanalisi. | EJ3: Indica la comparsa improvvisa di un desiderio impellente e improcrastinabile di urinare, difficile da rimandare, spesso associato a infezioni delle basse vie urinarie (cistite) o irritazione vescicale. | EK3: Indica un aumento anomalo della frequenza delle minzioni durante le 24 ore, con emissione di piccole quantità di urina ogni volta, non correlato a un aumento dell'introito di liquidi. | EL3: Indica la presenza di dolore, bruciore o fastidio durante l'emissione di urina, spesso associato a difficoltà nell'iniziare la minzione; è un segno tipico di infiammazione o infezione dell'uretra e della vescica. | EM3: Indica la presenza di dolore, tensione o senso di peso localizzato nella regione ipogastrica (parte inferiore dell'addome, sopra l'osso pubico), tipicamente associato a processi infiammatori o infettivi della vescica (cistite). | EN3: Indica la positività alla manovra di Giordano, ovvero l'insorgenza di dolore acuto alla percussione della loggia renale (angolo costovertebrale). È un segno clinico indicativo di infiammazione renale, tipico della pielonefrite o di calcolosi ostruttiva. | EO3: Indica la presenza di un catetere vescicale a dimora al momento della valutazione o la sua rimozione avvenuta nelle 48 ore precedenti; tale condizione è un fattore di rischio per infezioni delle vie urinarie | EP3: Indica la documentazione radiologica di una raccolta purulenta intra-addominale o pelvica tramite Tomografia Computerizzata (TC), Risonanza Magnetica (RM) o Ecografia (Eco). | EQ3: Indica il riscontro obiettivo di materiale purulento (pus) all'interno della cavità addominale o di un organo, documentato dal chirurgo durante un intervento (laparotomico o laparoscopico) o una procedura di drenaggio. | ER3: Indica il riscontro intraoperatorio di una raccolta purulenta circoscritta (ascesso) o di una cavità ascessuale documentata dal chirurgo nel verbale operatorio, sia essa integra o drenata durante la procedura. | ES3: Indica la sensazione soggettiva di sgradevolezza e di imminente bisogno di vomitare, riferita dal paziente, localizzata tipicamente alla gola o all'epigastrio, che può precedere o meno l'emesi (vomito). | ET3: Indica l'espulsione forzata e involontaria del contenuto gastrico attraverso la bocca (emesi), oggettivamente rilevata o riferita dal paziente, indipendentemente dalla natura del materiale espulso. | EU3: Indica la presenza di dolore o fastidio localizzato in una qualsiasi regione dell'addome, riferito dal paziente o rilevato durante la palpazione. Include descrizioni di dolore crampiforme, trafittivo, gravativo o diffuso. | EV3: Indica una condizione clinica d'emergenza caratterizzata da dolore addominale violento e segni obiettivi di irritazione peritoneale (es. addome a tavola, difesa addominale involontaria, assenza di rumori intestinali) che suggeriscono una patologia intraddominale grave, spesso di pertinenza chirurgica. | EW3: Indica la fuoriuscita di materiale francamente purulento (pus), denso e opaco, dai drenaggi chirurgici precedentemente posizionati all'interno della cavità addominale. Il riscontro deve essere documentato nelle note infermieristiche o nel diario clinico. | EX3: Indica la presenza di secrezione purulenta (pus) che fuoriesce spontaneamente o dopo manovra di spremitura dai margini della ferita chirurgica o dall'incisione. È un criterio clinico primario per la diagnosi di infezione del sito chirurgico superficiale o profonda. | EY3: Indica la presenza di dolore localizzato o dolorabilità alla palpazione in corrispondenza della ferita chirurgica, che può manifestarsi come sintomo riferito dal paziente o come segno obiettivo di flogosi locale durante la medicazione. | EZ3: Indica la presenza di gonfiore o tumefazione localizzata (edema) dei tessuti circostanti la ferita chirurgica, spesso associato a tensione dei margini, che può suggerire un accumulo di liquidi (sieroma, ematoma) o un processo infettivo in corso. | FA3: Indica la presenza di arrossamento cutaneo (eritema) localizzato lungo i margini della ferita chirurgica o nei tessuti circostanti l'incisione, indicativo di infiammazione o infezione in atto. | FB3: Indica un aumento della temperatura cutanea percepibile al tatto (ipertermia locale) in corrispondenza della ferita chirurgica o dei tessuti perilesionali, segno di aumentata vascolarizzazione dovuta a infiammazione o infezione. | FC3: Indica la separazione parziale o totale dei margini della ferita chirurgica, precedentemente suturata, che avviene in modo non intenzionale (spontaneo). Può interessare i soli strati superficiali (cute/sottocute) o quelli profondi (fascia/muscolo). | FD3: Indica la riapertura intenzionale dei margini della ferita chirurgica effettuata dal chirurgo (es. rimozione di punti o agrette), motivata dal sospetto clinico di un'infezione profonda, un ascesso o un ematoma sottocutaneo. | FE3: Indica la presenza di una diagnosi formale e documentata in cartella clinica di 'Infezione del Sito Chirurgico' (SSI), superficiale o profonda, o di 'Infezione della ferita chirurgica', espressa esplicitamente dal medico o dal chirurgo. | FF3: Indica la documentazione in cartella clinica di essudato o secrezioni di aspetto purulento (pus), dense e di colore variabile (giallastro, verdastro, grigiastro), provenienti da una lesione cutanea, un'ulcera o un'area di flogosi dei tessuti molli. | FG3: Indica il riscontro clinico di pustole, piccole lesioni cutanee rilevate, circoscritte e a contenuto purulento (pus), documentate in cartella clinica. Sono tipiche di processi infettivi superficiali come follicoliti, impetigine o altre piodermiti. | FH3: Indica il riscontro clinico di un'infiammazione acuta e profonda dell'apparato pilo-sebaceo (foruncolo), caratterizzata da un nodulo dolente, eritematoso e con tendenza alla necrosi centrale (fittone). Può essere segnalato come singolo o multiplo (foruncolosi). | FI3: Indica la segnalazione in cartella di dolore, dolenzia o iperalgesia circoscritta a un'area specifica della cute o dei tessuti sottostanti. Il dolore può essere spontaneo o evocato dalla palpazione e rappresenta uno dei segni cardine della flogosi locale (SST). | FJ3: Indica il riscontro clinico di un aumento della temperatura cutanea circoscritto a una specifica area del corpo (ipertermia locale), percepito al tatto o tramite termometria cutanea. È un segno semeiologico fondamentale di infiammazione o infezione sottostante (es. cellulite o ascesso). | FK3: Indica il riscontro in cartella clinica di eritema o arrossamento della cute perilesionale (attorno ai bordi) di un'ulcera da decubito. È un segno indicativo di flogosi locale, potenziale colonizzazione batterica critica o infezione del tessuto cutaneo circostante. | FL3: Indica la presenza di indurimento dei tessuti (edema duro o induramento) situati lungo il perimetro o nella zona perilesionale di un'ulcera da decubito. Tale reperto, rilevato alla palpazione, può suggerire un'estensione dell'infezione ai tessuti molli profondi o la formazione di una tasca ascessuale. | FM3: Indica il riscontro documentato di essudato purulento (pus) che drena dal letto o dai bordi di un'ulcera da decubito. Il materiale è tipicamente denso, opaco e di colore variabile (giallastro, verdastro o brunastro), segno clinico di infezione locale in atto. | FN3: Indica il riscontro radiologico di segni compatibili con infezione ossea (osteomielite) tramite Radiografia (RX), Risonanza Magnetica (RM), Tomografia Computerizzata (TC) o Scintigrafia. Include evidenze di erosione ossea, reazione periostale, sequestri ossei o edema midollare (in RM). | FO3: Indica la segnalazione di dolore profondo, persistente e localizzato in corrispondenza di un segmento osseo, spesso accentuato dalla pressione o dal carico. Nel contesto clinico, è un sintomo cardine riferito dal paziente che suggerisce un processo infiammatorio o infettivo a carico dell'osso (osteomielite). | FP3: Indica il riscontro di tumefazione o edema dei tessuti molli sovrastanti un segmento osseo sospetto per infezione. Il gonfiore è spesso associato a tensione cutanea e può riflettere un'infiammazione periostale o la formazione di un ascesso sottoperiostale/extraparietale (osteomielite). | FQ3: Indica la segnalazione di mal di testa (cefalea) di nuova insorgenza o peggioramento di una cefalea cronica. Nel sospetto di meningite, è spesso descritta come intensa, diffusa (olocranica) e talvolta associata a fotofobia o fonofobia. | FR3: Indica la resistenza o l'impossibilità di flettere passivamente il capo verso il torace a causa della contrattura dei muscoli nucali. È un segno patognomonico di irritazione meningea, spesso rilevato insieme ai segni di Brudzinski o Kerning durante l'esame obiettivo neurologico. | FS3: Indica la presenza di deficit neurologici focali a carico dei nervi cranici (I-XII), come alterazioni della motilità oculare, asimmetria facciale, ptosi palpebrale, diplopia o disfagia. Nel contesto di una meningite, possono indicare un processo infiammatorio basale o una complicanza compressiva. | FT3: Indica il riscontro di un numero di globuli bianchi (leucociti) nel liquido cerebrospinale superiore ai valori di riferimento (pleiocitosi), solitamente $> 5$ cellule/$\mu L$. Il parametro documenta la presenza di infiammazione delle meningi, distinguendo tra prevalenza di neutrofili (tipica delle forme batteriche) o linfociti (tipica delle forme virali/tubercolari). | FU3: Indica una concentrazione di glucosio nel liquido cefalorachidiano (glicorachia) inferiore ai valori di riferimento, solitamente $< 40$ mg/dL o con un rapporto liquor/sangue $< 0.6$. Il consumo di glucosio (ipoglicorachia) è un segno tipico di meningite batterica, tubercolare o fungina, dovuto al metabolismo dei patogeni e delle cellule infiammatorie. | FV3: Indica il riscontro ecocardiografico (transtoracico o transesofageo) di una massa intracardiaca oscillante (vegetazione) su una valvola, sulle strutture di supporto, nel tragitto di getti rigurgitanti o su materiale protesico, in assenza di un'altra spiegazione anatomica. | FW3: Indica il riscontro all'auscultazione cardiaca di un soffio di nuova insorgenza o il significativo cambiamento (accentuazione o variazione di timbro) di un soffio preesistente. È un segno indicativo di rigurgito valvolare acuto o turbolenza emodinamica causata da vegetazioni o distruzione tessutale valvolare. | FX3: Indica il riscontro ecocardiografico (ETT o ETE) o radiologico (TC cardiaca) di una zona ecopriva (vuota) o ipodensa situata nel tessuto perivalvolare o nel miocardio adiacente, non comunicante con il lume cardiaco. Rappresenta una complicanza suppurativa dell'endocardite infettiva che coinvolge l'anello valvolare o il setto. | FY3: "Categorise as adult BSI case any non-neonate patient with: 1) One positive blood culture for a recognised pathogen OR patient has at least one of the following signs or symptoms: fever (>38°C), chills, or hypotension AND two positive blood cultures for a common skin contaminant8 (from two separate blood samples, usually within 48 hours)." fonte Definizione BSI PPS ECDC | FZ3: BSI che non rientra nella definizione di HA-BSI | GA3: "A BSI case is considered healthcare-associated (HA-BSI) when it meets any of the following criteria: - Day 3 onwards (with day of admission being Day 1) OR - Day 1 or Day 2 AND patient discharged from healthcare facility in preceding 48 hours. OR - Day 1 or Day 2 AND patient has relevant device inserted on this admission prior to onset. OR - Day 1 or Day 2 in newborns delivered in hospital." Fonte ECDC PPS | GB3: "CRI3-CVC/CRI3-PVC9: Catheter related with cultural isolation of the same microorganism. More specifically: BSI occurring 48 hours before or after catheter removal AND positive culture with the same microorganism of quantitative CVC/PVC culture ≥ 103 CFU/ml or semi-quantitative CVC/PVC culture > 15 CFU; OR BSI occurring with or without catheter removal, AND: CVC-related if at least one of: quantitative blood culture ratio of CVC blood sample/peripheral blood sample > 5; differential delay of positivity of blood cultures: CVC blood sample culture positive two hours or more before peripheral blood culture (blood samples drawn at the same time); positive culture with the same microorganism from pus from CVC insertion site. PVC-related if positive culture with the same microorganism from pus from insertion site." Fonte ECDC PPS | GC3: "CRI3-CVC/CRI3-PVC9: Catheter related with cultural isolation of the same microorganism. More specifically: BSI occurring 48 hours before or after catheter removal AND positive culture with the same microorganism of quantitative CVC/PVC culture ≥ 103 CFU/ml or semi-quantitative CVC/PVC culture > 15 CFU; OR BSI occurring with or without catheter removal, AND: CVC-related if at least one of: quantitative blood culture ratio of CVC blood sample/peripheral blood sample > 5; differential delay of positivity of blood cultures: CVC blood sample culture positive two hours or more before peripheral blood culture (blood samples drawn at the same time); positive culture with the same microorganism from pus from CVC insertion site. PVC-related if positive culture with the same microorganism from pus from insertion site." Fonte ECDC PPS | GD3: "C-CVC/C-PVC: Catheter related due to clinical suspicion (e.g., symptoms improve within 48 hours after catheter removal) AND no microbiological confirmation." Fonte ECDC PPS | GE3: "C-CVC/C-PVC: Catheter related due to clinical suspicion (e.g., symptoms improve within 48 hours after catheter removal) AND no microbiological confirmation." Fonte ECDC PPS | GF3: "the same microorganism was isolated from another infection site, or strong clinical evidence exists that bloodstream infection was secondary to another infection site, invasive diagnostic procedure or foreign body:" Fonte ECDC PPS | GG3: pulmonary | GH3: urinary tract infection | GI3: digestive tract infection | GJ3: surgical site infection | GK3: skin and soft tissue | GL3: other | GM3: "Unknown origin (UO): none of the above, bloodstream infection of unknown source." Fonte ECDC PPS | GN3: "NEO-LCBI – for BSI in neonatal patients (less than 1 month from birth) with positive microbiology (excluding coagulase-negative staphylococci). Categorise as NEO-LCBI case neonate patient with: - At least two of: temperature >38°C or <36.5°C or temperature instability, tachycardia or bradycardia, apnoea, extended capillary refilling time (CRT), metabolic acidosis, hyperglycaemia, other sign of BSI such as apathy; AND - A recognised pathogen other than coagulase-negative staphylococci (CNS) cultured from blood or cerebrospinal fluid (CSF; this is included because meningitis in this age group is usually haematogenous, so positive CSF can be regarded as evidence of BSI even if blood cultures are negative or were not taken)." Fonte ECDC PPS | GO3: "NEO-CNSB - for BSI in neonatal patients (less than 1 month from birth) with coagulase-negative staphylococci detection. Categorise as NEO-CNSB case neonate patient with: - At least two of: temperature > 38°C or < 36.5°C or temperature instability, tachycardia or bradycardia, apnoea, extended capillary refilling time, metabolic acidosis, hyperglycaemia, other sign of BSI such as apathy; AND - CNS is cultured from blood or catheter tip; AND - Patient has one of: C-reactive protein > 2.0 mg/dL, immature/total neutrophil ratio (I/T ratio) > 0.2, leukocytes < 5/nL, platelets < 100/nL. If both the case definitions for NEO-LCBI and NEO-CNSB are matched, report NEO-LCBI." Fonte ECDC PPS | GP3: Infection is associated with (CURR) current hospital | GQ3: Infection is associated with another hospital. Infections present at admission may be associated with a previous stay in your hospital or a transfer from another healthcare facility. | GR3: Infection is associated with a long-term care facility. Infections present at admission may be associated with a previous stay in your hospital or a transfer from another healthcare facility. | GS3: Infection is associated with other origin or unknown. The category ‘other origin or unknown’ can be used, for example, for infections with an onset after day 2 of the current hospitalisation for which the association is not clear.
A4: Descrizione del parametro sintetica | B4: SE età <= 30 giorni al momento dell'insorgenza dell'infezione. | C4: SE temperatura corporea >= 38,0 gradi C | D4: temperatura corporea massima in gradi C | E4: data temperatura corporea massima | F4: SE temperatura corporea < 36,5 gradi C | G4: temperatura corporea minima in gradi C | H4: data temperatura corporea minima | I4: SE brividi (freddo e tremore muscolare involontario) | J4: data brividi | K4: SE pressione sistolica < 90mmHg o diastolica < 60mmHg | L4: pressione sistolica minima in mmHg | M4: data pressione sistolica minima | N4: pressione diastolica minima in mmHg | O4: data pressione diastolica minima | P4: SE frequenza cardiaca > 160bpm | Q4: frequenza cardiaca massima in bpm | R4: data frequenza cardiaca massima | S4: SE frequenza cardiaca < 100bpm | T4: frequenza cardiaca minima in bpm | U4: data frequenza cardiaca minima | V4: SE apnea lunga OPPURE (apnea corta E (bradicardia O cianosi O pallore O ipotonia marcata)) | W4: SE durata apnea >= 20 secondi | X4: SE durata apnea >= 5 E <= 19 secondi | Y4: tempo apnea massimo in secondi | Z4: data apnea massima | AA4: SE cianosi (colorazione bluastra o violacea per ridotta ossigenazione) | AB4: data cianosi | AC4: SE pallore cutaneo (pelle o mucose più chiare per ridotto flusso o bassa emoglobina) | AD4: data pallore cutaneo | AE4: SE ipotonia marcata (riduzione severa tono muscolare, postura a 'bambola di pezza') | AF4: data ipotonia marcata | AG4: numero totale emocolture positive | AH4: data prima emocoltura positiva | AI4: ora prima emocoltura positiva | AJ4: data seconda emocoltura positiva | AK4: ora seconda emocoltura positiva | AL4: ore tra prima e seconda emocoltura | AM4: SE intervallo tra prima e seconda emocoltura < 48 ore | AN4: genere e specie primo microrganismo isolato in emocoltura | AO4: SE primo microrganismo isolato in emocoltura è patogeno significativo (NON contaminante) | AP4: SE primo microrganismo isolato in emocoltura è potenziale contaminante cutaneo | AQ4: genere e specie secondo microrganismo isolato in emocoltura | AR4: SE secondo microrganismo isolato in emocoltura è patogeno significativo (NON contaminante) | AS4: SE secondo microrganismo isolato in emocoltura è potenziale contaminante cutaneo | AT4: SE microrganismo isolato in emocoltura è stafilococco coagulasi-negativo (CNS) | AU4: numero totale colture liquor positive | AV4: data prelievo liquido cerebrospinale (liquor) | AW4: genere e specie microrganismo isolato nel liquor | AX4: SE microrganismo isolato nel liquor è stafilococco coagulasi-negativo (CNS) | AY4: numero totale isolamenti da CVC | AZ4: data prelievo da CVC | BA4: ora prelievo da CVC | BB4: genere e specie microrganismo isolato da CVC | BC4: SE microrganismo isolato da CVC è stafilococco coagulasi-negativo (CNS) | BD4: numero totale isolamenti da CVP | BE4: data prelievo da CVP | BF4: ora prelievo da CVP | BG4: genere e specie microrganismo isolato da CVP | BH4: SE microrganismo isolato da CVP è stafilococco coagulasi-negativo (CNS) | BI4: SE Proteina C Reattiva (PCR) > 2,0 mg/dL | BJ4: valore massimo Proteina C Reattiva (PCR) in mg/dL | BK4: data valore massimo Proteina C Reattiva (PCR) | BL4: SE rapporto neutrofili immaturi/totali (I/T ratio) > 0,2 | BM4: valore massimo rapporto neutrofili immaturi/totali (I/T ratio) | BN4: data valore massimo rapporto neutrofili immaturi/totali (I/T ratio) | BO4: SE leucociti < 5/nL | BP4: valore minimo leucociti in /nL | BQ4: data valore minimo leucociti (globuli bianchi) | BR4: SE piastrine < 100/nL | BS4: valore minimo piastrine in /nL | BT4: data valore minimo piastrine | BU4: data ammissione in ospedale | BV4: ora ammissione in ospedale | BW4: luogo di provenienza del paziente al ricovero | BX4: data inserimento dispositivo medico invasivo durante il ricovero | BY4: SE presenza di dispositivo medico invasivo all'ammissione | BZ4: tipologia dispositivo medico invasivo inserito durante il ricovero | CA4: SE paziente nato nella stessa struttura del ricovero (inborn) | CB4: data rimozione catetere venoso centrale (CVC) | CC4: ora rimozione catetere (CVC o CVP) | CD4: carica batterica quantitativa da catetere in CFU/mL | CE4: carica batterica semiquantitativa da catetere in CFU | CF4: SE rapporto emocoltura quantitativa CVC/sangue periferico > 5 | CG4: SE Differential Time to Positivity (DTP) CVC/sangue periferico > 2 ore | CH4: differenziale temporale di positività (DTP) tra CVC e sangue periferico | CI4: SE presenza di colture positive da materiale purulento (pus) da sito CVC | CJ4: data prelievo materiale purulento (pus) da sito o tunnel CVC | CK4: microrganismo isolato da materiale purulento (pus) da sito o tunnel CVC | CL4: SE presenza di colture positive da materiale purulento (pus) da sito CVP | CM4: data prelievo materiale purulento (pus) da sito CVP | CN4: microrganismo isolato da materiale purulento (pus) da sito CVP | CO4: SE miglioramento clinico entro 48 ore dalla rimozione del catetere (CVC/CVP) | CP4: data rimozione catetere (CVC o CVP) sospetto sito d'infezione | CQ4: ultima temperatura corporea pre-rimozione catetere (CVC/CVP) | CR4: temperatura corporea a 48 ore dalla rimozione del catetere (CVC/CVP) | CS4: SE miglioramento o risoluzione dello stato febbrile entro 48 ore dalla rimozione del catetere (CVC/CVP) | CT4: SE presenza di eritema al sito di inserzione del catetere (CVC o CVP) pre-rimozione | CU4: SE presenza o persistenza di eritema al sito di inserzione 48 ore dopo la rimozione del catetere (CVC o CVP) | CV4: SE riduzione o risoluzione dell'eritema al sito di inserzione entro 48 ore dalla rimozione del catetere (CVC/CVP) | CW4: presenza di pus al sito di inserzione del catetere (CVC o CVP) pre-rimozione | CX4: presenza di pus al sito di inserzione 48 ore dopo la rimozione del catetere (CVC o CVP) | CY4: riduzione del pus al sito di inserzione entro 48 ore dalla rimozione del catetere (CVC/CVP) | CZ4: SE coltura BAL positiva con carica >= 10^4 CFU/ml | DA4: data coltura BAL positiva | DB4: nome microrganismo isolato da BAL | DC4: SE coltura aspirato tracheale positiva con carica >= 10^5 CFU/ml | DD4: data coltura aspirato tracheale positiva | DE4: nome microrganismo isolato da aspirato tracheale | DF4: SE coltura escreato positiva con campione idoneo per Score di Murray | DG4: data coltura escreato positiva | DH4: nome microrganismo isolato da escreato clinicamente significativo | DI4: SE urinocoltura positiva con carica >= 10^5 CFU/ml | DJ4: data urinocoltura positiva | DK4: nome microrganismo isolato da urinocoltura significativa | DL4: SE tampone ferita chirurgica positivo con isolamento microrganismi patogeni | DM4: data tampone ferita chirurgica positivo | DN4: nome microrganismo isolato da tampone ferita chirurgica | DO4: SE biopsia tessuto positiva con isolamento microrganismi patogeni tramite coltura o istologia | DP4: data biopsia tessuto positiva | DQ4: nome microrganismo isolato da biopsia tessuto tramite coltura o indagine molecolare | DR4: SE coltura ascesso positiva con isolamento microrganismi patogeni da aspirazione o drenaggio | DS4: data coltura ascesso positiva | DT4: nome microrganismo isolato da coltura ascesso | DU4: SE coltura protesi o liquido di sonicazione positiva con isolamento microrganismi patogeni | DV4: data coltura protesi o liquido di sonicazione positiva | DW4: nome microrganismo isolato da coltura o sonicazione protesi | DX4: SE presenza di nuovi o progressivi infiltrati, consolidamenti o opacita alla RX torace | DY4: SE presenza di aree di consolidamento parenchimale alla RX torace | DZ4: SE presenza di cavita a contenuto aereo o idroaereo alla RX torace | EA4: SE presenza di segni TC quali ground-glass, consolidamenti, noduli con segno alone o linfoadenopatie ilari | EB4: SE presenza di tosse secca o produttiva | EC4: SE presenza di difficolta respiratoria o aumento sforzo respiratorio o tachipnea o necessità di ossigeno supplementare | ED4: SE frequenza respiratoria > 20 atti/minuto | EE4: SE presenza di espettorato purulento (giallastro o verdastro) denso e opaco tramite tosse | EF4: SE presenza di sangue dalle vie respiratorie tramite tosse (espettorato ematico) | EG4: SE presenza di rumori respiratori secchi (ronchi) all'auscultazione | EH4: SE presenza di alterazioni del murmure vescicolare, riduzione o assenza del respiro o rumori patologici aggiunti non specificati all'auscultazione toracica | EI4: SE saturazione ossigeno nel sangue (SpO2) < 91% | EJ4: SE presenza di desiderio improvviso e impellente di urinare difficile da rimandare | EK4: SE aumento frequenza minzioni nelle 24 ore con piccole quantità di urina non correlate a maggiori liquidi | EL4: SE presenza di dolore, bruciore o fastidio durante l'emissione di urina o difficoltà nell'iniziare la minzione | EM4: SE presenza di dolore, tensione o senso di peso in regione ipogastrica | EN4: SE dolore acuto alla percussione della loggia renale indicativo di infiammazione renale o calcolosi | EO4: SE presenza di catetere vescicale a dimora o rimosso nelle 48 ore precedenti | EP4: SE presenza di ascesso addominale o pelvico documentato tramite TC, RM o Ecografia | EQ4: SE presenza di pus in cavità addominale o organo rilevata durante intervento chirurgico o drenaggio | ER4: SE presenza di ascesso o cavità ascessuale documentata dal chirurgo durante intervento o procedura di drenaggio | ES4: SE presenza di nausea | ET4: SE presenza di episodi di vomito (emesi) | EU4: SE presenza di dolore a livello addominale riferito o alla palpazione | EV4: SE dolore addominale violento con segni di irritazione peritoneale (addome a tavola, difesa involontaria, assenza rumori intestinali) | EW4: SE presenza di pus dai drenaggi chirurgici addominali | EX4: SE presenza di pus dai margini della ferita o dall'incisione (spontanea o dopo spremitura) | EY4: SE presenza di dolore localizzato o dolorabilità alla palpazione della ferita chirurgica | EZ4: SE presenza di edema dei tessuti circostanti la ferita chirurgica o tensione dei margini | FA4: SE presenza di eritema localizzato lungo i margini o nei tessuti circostanti la ferita chirurgica | FB4: SE presenza di calore o aumento della temperatura cutanea percepibile al tatto sulla ferita chirurgica o tessuti perilesionali | FC4: SE separazione parziale o totale dei margini della ferita chirurgica che avviene in modo spontaneo (superficiale o profondo) | FD4: SE riapertura intenzionale dei margini della ferita effettuata dal chirurgo per sospetta infezione, ascesso o ematoma | FE4: SE presenza di diagnosi formale di Infezione del Sito Chirurgico (SSI) o della ferita chirurgica | FF4: SE presenza di essudato o secrezioni purulente (pus) da lesione cutanea, ulcera o tessuti molli | FG4: SE presenza di pustole (piccole lesioni circoscritte a contenuto purulento) | FH4: SE presenza di foruncoli con nodulo dolente, eritematoso e necrosi centrale | FI4: SE dolore, dolenzia o iperalgesia in area specifica cute o tessuti sottostanti | FJ4: SE ipertermia locale cutanea in area specifica o tessuti sottostanti | FK4: SE eritema perilesionale di ulcera da decubito | FL4: SE indurimento dei tessuti perilesionali di ulcera da decubito | FM4: SE presenza di pus drenante da ulcera da decubito | FN4: SE presenza di segni radiologici di osteomielite (RX, RM, TC o scintigrafia) | FO4: SE presenza di dolore profondo, persistente e localizzato su segmento osseo | FP4: SE presenza di tumefazione o edema dei tessuti molli sovrastanti un segmento osseo | FQ4: SE presenza di cefalea intensa di nuova insorgenza o olocranica (sospetto meningite) | FR4: SE presenza di resistenza o impossibilità di flessione passiva del capo per contrattura muscoli nucali | FS4: SE presenza di deficit neurologici focali dei nervi cranici (es. motilità oculare, asimmetria facciale, diplopia) | FT4: SE presenza di pleiocitosi liquorale (leucociti > 5 cellule/uL) indicativa di infiammazione meningea | FU4: SE presenza di concentrazione glucosio nel liquor < 40 mg/dL o rapporto liquor/sangue < 0.6 | FV4: SE presenza di massa intracardiaca oscillante (vegetazione) rilevata all'ecocardiografia (TTE o TEE) | FW4: SE presenza di nuovo soffio cardiaco o variazione significativa di un soffio preesistente | FX4: SE presenza di ascesso - zona ecopriva o ipodensa - in tessuto perivalvolare o miocardio (ETT, ETE o TC)
